Workbook

Sheet dinamica
C2: INGRESO | D2: 0.33333333
C3: SALIDA | D3: 0.70833333 | E3: PROYECTADO
B4: DIA | C4: RECORRIDO | D4: JORNADA | E4: PARADERO1 | F4: PARADERO2 | G4: HORARIO-P1 | H4: HORARIO-P2 | I4: TIEMPO APROXIMADO DE RECORRIDO Y RETORNO (mts)
C5: R1 | D5: MAÑANA | E5: ESTACIÓN TMS | F5: KOA | G5: 0.27083333 | H5: =+G5+I5/2 -> 0.28125 | I5: =+G6-G5 -> 0.020833333
C6: R2 | D6: MAÑANA | E6: ESTACIÓN TMS | F6: KOA | G6: 0.29166667 | H6: =+G6+I6/2 -> 0.30729167 | I6: =+G7-G6 -> 0.03125
C7: R3 | D7: MAÑANA | E7: ESTACIÓN TMS | F7: KOA | G7: 0.32291667 | H7: =+G7+I7/2 -> 0.328125 | I7: =+D2-G7 -> 0.010416667
C8: R1 | D8: TARDE | E8: KOA | F8: ESTACIÓN TMS | G8: 0.71527778 | H8: =+G8+I8/2 -> 0.72743056 | I8: =+G9-G8 -> 0.024305556
C9: R2 | D9: TARDE | E9: KOA | F9: ESTACIÓN TMS | G9: 0.73958333 | H9: =+G9+I9/2 -> 0.75173611 | I9: =+G10-G9 -> 0.024305556
C10: R3 | D10: TARDE | E10: KOA | F10: ESTACIÓN TMS | G10: 0.76388889 | H10: =+G10+I10/1440 -> 0.77569444 | I10: 17
C13: INGRESO | D13: 0.33333333
C14: SALIDA | D14: 0.70833333 | E14: HABITUAL
B15: DIA | C15: RECORRIDO | D15: JORNADA | E15: PARADERO1 | F15: PARADERO2 | G15: HORARIO | H15: HORARIO-P2 | I15: TIEMPO APROXIMADO DE RECORRIDO Y RETORNO (mts)
C16: R1 | D16: MAÑANA | E16: ESTACIÓN TMS | F16: KOA | G16: 0.27083333 | H16: =+G16+I16/2 -> 0.28125 | I16: =+G17-G16 -> 0.020833333
C17: R2 | D17: MAÑANA | E17: ESTACIÓN TMS | F17: KOA | G17: 0.29166667 | H17: =+G17+I17/2 -> 0.30208333 | I17: =+G18-G17 -> 0.020833333
C18: R3 | D18: MAÑANA | E18: ESTACIÓN TMS | F18: KOA | G18: 0.3125 | H18: =+G18+I18/2 -> 0.32291667 | I18: =+D13-G18 -> 0.020833333
C19: R1 | D19: TARDE | E19: KOA | F19: ESTACIÓN TMS | G19: 0.71527778 | H19: =+G19+I19/2 -> 0.72743056 | I19: =+G20-G19 -> 0.024305556
C20: R2 | D20: TARDE | E20: KOA | F20: ESTACIÓN TMS | G20: 0.73958333 | H20: =+G20+I20/2 -> 0.75173611 | I20: =+G21-G20 -> 0.024305556
C21: R3 | D21: TARDE | E21: KOA | F21: ESTACIÓN TMS | G21: 0.76388889 | H21: =+G21+I21/1440 -> 0.77569444 | I21: 17

Sheet Hoja1
A1: RECORRIDO | B1: JORNADA | C1: ORIGEN | D1: DESTINO | E1: HORARIO
A2: R1 | B2: MAÑANA | C2: ESTACIÓN HEROES | D2: KOA | E2: 6:30:00 a. m.
A3: R2 | B3: MAÑANA | C3: ESTACIÓN HEROES | D3: KOA | E3: 7:00:00 a. m.
A4: R3 | B4: MAÑANA | C4: ESTACIÓN HEROES | D4: KOA | E4: 7:30:00 a. m.
A5: R1 | B5: TARDE | C5: KOA | D5: ESTACIÓN (Virrey, Héroes y Polo) | E5: 5:10:00 p. m.
A6: R2 | B6: TARDE | C6: KOA | D6: ESTACIÓN (Virrey, Héroes y Polo) | E6: 5:45:00 p. m.
A7: R3 | B7: TARDE | C7: KOA | D7: ESTACIÓN (Virrey, Héroes y Polo) | E7: 6:20:00 p. m.

Sheet fest
A1: 46023
A2: 46034
A3: 46104
A4: 46114
A5: 46115
A6: 46143
A7: 46160
A8: 46181
A9: 46188
A10: 46223
A11: 46241
A12: 46251
... A18: 46202

Sheet seguimiento_h_op
A1: Tipo de jornada | B1: DIA DEL SERVICIO | C1: RECORRIDO | D1: JORNADA | E1: PARADERO1 | F1: PARADERO2 | G1: HORARIO-P1-REAL DE INICIO | H1: HORARIO-P2 REAL | I1: TIEMPO APROXIMADO DE RECORRIDO Y RETORNO (mts) | J1: Hora de posición(vh)R1P1 | K1: Hora de inicio R1P1 | L1: tiempo de espera vehiculo | M1: Hora de llegada a KOA P2 | N1: Tiempo de trayecto ida -regreso | O1: Tiempo REAL con gabela de espera | P1: usuarios | Q1: PARADAS | R1: diaop
A2: JM | B2: 46111 | C2: R1 | D2: MAÑANA | E2: ESTACIÓN TMS | F2: KOA | G2: 0.27083333 | H2: =+G2+I2 -> 0.29166667 | I2: =+G3-G2 -> 0.020833333 | J2: 0.26458333 | K2: 0.27361111 | L2: =+K2-J2 -> 0.0090277778 | M2: 0.28819444 | N2: =+M2-K2 -> 0.014583333 | O2: =+L2+N2 -> 0.023611111 | P2: 3 | Q2: OXXOHEROES | R2: =IF(COUNTIF(fest!$A$1:$A$18,B2)>0,"FESTIVO", IF(OR(WEEKDAY(B2,2)=6,WEEKDAY(B2,2)=7),"NO HÁBIL","HÁBIL")) -> HÁBIL
A3: JM | B3: 46111 | C3: R2 | D3: MAÑANA | E3: ESTACIÓN TMS | F3: KOA | G3: 0.29166667 | H3: =+G3+I3 -> 0.3125 | I3: =+G4-G3 -> 0.020833333 | J3: 0.28819444 | K3: 0.29375 | L3: =+K3-J3 -> 0.0055555556 | M3: 0.30972222 | N3: =+M3-K3 -> 0.015972222 | O3: =+L3+N3 -> 0.021527778 | P3: 3 | Q3: OXXOHEROES | R3: =IF(COUNTIF(fest!$A$1:$A$18,B3)>0,"FESTIVO", IF(OR(WEEKDAY(B3,2)=6,WEEKDAY(B3,2)=7),"NO HÁBIL","HÁBIL")) -> HÁBIL
A4: JM | B4: 46111 | C4: R3 | D4: MAÑANA | E4: ESTACIÓN TMS | F4: KOA | G4: 0.3125 | H4: =+G4+I4 -> 0.71527778 | I4: =+G5-G4 -> 0.40277778 | J4: 0.30972222 | K4: 0.31527778 | L4: =+K4-J4 -> 0.0055555556 | M4: =+K4+N4 -> 0.33055556 | N4: =AVERAGE(N2:N3) -> 0.015277778 | O4: =+L4+N4 -> 0.020833333 | P4: 1 | Q4: OXXOHEROES | R4: =IF(COUNTIF(fest!$A$1:$A$18,B4)>0,"FESTIVO", IF(OR(WEEKDAY(B4,2)=6,WEEKDAY(B4,2)=7),"NO HÁBIL","HÁBIL")) -> HÁBIL
A5: JT | B5: 46111 | C5: R1 | D5: TARDE | E5: KOA | F5: ESTACIÓN TMS | G5: 0.71527778 | H5: =+G5+I5 -> 0.73958333 | I5: =+G6-G5 -> 0.024305556 | J5: 0.70902778 | K5: 0.71666667 | L5: =+K5-J5 -> 0.0076388889 | M5: 0.73402778 | N5: =+M5-K5 -> 0.017361111 | O5: =+L5+N5 -> 0.025 | P5: 5 | Q5: VIRREY Y POLO | R5: =IF(COUNTIF(fest!$A$1:$A$18,B5)>0,"FESTIVO", IF(OR(WEEKDAY(B5,2)=6,WEEKDAY(B5,2)=7),"NO HÁBIL","HÁBIL")) -> HÁBIL
A6: JT | B6: 46111 | C6: R2 | D6: TARDE | E6: KOA | F6: ESTACIÓN TMS | G6: 0.73958333 | H6: =+G6+I6 -> 0.76388889 | I6: =+G7-G6 -> 0.024305556 | J6: 0.73402778 | K6: 0.74722222 | L6: =+K6-J6 -> 0.013194444 | M6: 0.75694444 | N6: =+M6-K6 -> 0.0097222222 | O6: =+L6+N6 -> 0.022916667 | P6: 0 | Q6: NO SALIERON USUARIOS | R6: =IF(COUNTIF(fest!$A$1:$A$18,B6)>0,"FESTIVO", IF(OR(WEEKDAY(B6,2)=6,WEEKDAY(B6,2)=7),"NO HÁBIL","HÁBIL")) -> HÁBIL
A7: JT | B7: 46111 | C7: R3 | D7: TARDE | E7: KOA | F7: ESTACIÓN TMS | G7: 0.76388889 | H7: =+G7+I7 -> 0.27083333 | I7: =+G8-G7 -> -0.49305556 | J7: 0.75694444 | K7: 0.76597222 | L7: =+K7-J7 -> 0.0090277778 | M7: =+K7+N7 -> 0.77951389 | N7: =AVERAGE(N5:N6) -> 0.013541667 | O7: =+L7+N7 -> 0.022569444 | P7: 5 | Q7: VIRREY Y POLO | R7: =IF(COUNTIF(fest!$A$1:$A$18,B7)>0,"FESTIVO", IF(OR(WEEKDAY(B7,2)=6,WEEKDAY(B7,2)=7),"NO HÁBIL","HÁBIL")) -> HÁBIL
A8: JM | B8: 46112 | C8: R1 | D8: MAÑANA | E8: ESTACIÓN TMS | F8: KOA | G8: 0.27083333 | H8: =+G8+I8 -> 0.29166667 | I8: =+G9-G8 -> 0.020833333 | J8: 0.26388889 | K8: 0.27430556 | L8: =+K8-J8 -> 0.010416667 | M8: 0.28888889 | N8: =+M8-K8 -> 0.014583333 | O8: =+L8+N8 -> 0.025 | P8: 4 | Q8: OXXOHEROES | R8: =IF(COUNTIF(fest!$A$1:$A$18,B8)>0,"FESTIVO", IF(OR(WEEKDAY(B8,2)=6,WEEKDAY(B8,2)=7),"NO HÁBIL","HÁBIL")) -> HÁBIL
A9: JM | B9: 46112 | C9: R2 | D9: MAÑANA | E9: ESTACIÓN TMS | F9: KOA | G9: 0.29166667 | H9: =+G9+I9 -> 0.3125 | I9: =+G10-G9 -> 0.020833333 | J9: 0.28888889 | K9: 0.29375 | L9: =+K9-J9 -> 0.0048611111 | M9: 0.31041667 | N9: =+M9-K9 -> 0.016666667 | O9: =+L9+N9 -> 0.021527778 | P9: 3 | Q9: OXXOHEROES | R9: =IF(COUNTIF(fest!$A$1:$A$18,B9)>0,"FESTIVO", IF(OR(WEEKDAY(B9,2)=6,WEEKDAY(B9,2)=7),"NO HÁBIL","HÁBIL")) -> HÁBIL
A10: JM | B10: 46112 | C10: R3 | D10: MAÑANA | E10: ESTACIÓN TMS | F10: KOA | G10: 0.3125 | H10: =+G10+I10 -> 0.71527778 | I10: =+G11-G10 -> 0.40277778 | J10: 0.31041667 | K10: 0.31666667 | L10: =+K10-J10 -> 0.00625 | M10: =+K10+N10 -> 0.33229167 | N10: =AVERAGE(N8:N9) -> 0.015625 | O10: =+L10+N10 -> 0.021875 | P10: 1 | Q10: OXXOHEROES | R10: =IF(COUNTIF(fest!$A$1:$A$18,B10)>0,"FESTIVO", IF(OR(WEEKDAY(B10,2)=6,WEEKDAY(B10,2)=7),"NO HÁBIL","HÁBIL")) -> HÁBIL
A11: JT | B11: 46112 | C11: R1 | D11: TARDE | E11: KOA | F11: ESTACIÓN TMS | G11: 0.71527778 | H11: =+G11+I11 -> 0.73958333 | I11: =+G12-G11 -> 0.024305556 | J11: 0.70833333 | K11: 0.71666667 | L11: =+K11-J11 -> 0.0083333333 | M11: 0.73333333 | N11: =+M11-K11 -> 0.016666667 | O11: =+L11+N11 -> 0.025 | P11: 1 | Q11: VIRREY Y POLO | R11: =IF(COUNTIF(fest!$A$1:$A$18,B11)>0,"FESTIVO", IF(OR(WEEKDAY(B11,2)=6,WEEKDAY(B11,2)=7),"NO HÁBIL","HÁBIL")) -> HÁBIL
A12: JT | B12: 46112 | C12: R2 | D12: TARDE | E12: KOA | F12: ESTACIÓN TMS | G12: 0.73958333 | H12: =+G12+I12 -> 0.76388889 | I12: =+G13-G12 -> 0.024305556 | J12: 0.73333333 | K12: 0.74166667 | L12: =+K12-J12 -> 0.0083333333 | M12: 0.75902778 | N12: =+M12-K12 -> 0.017361111 | O12: =+L12+N12 -> 0.025694444 | P12: 1 | Q12: VIRREY Y POLO | R12: =IF(COUNTIF(fest!$A$1:$A$18,B12)>0,"FESTIVO", IF(OR(WEEKDAY(B12,2)=6,WEEKDAY(B12,2)=7),"NO HÁBIL","HÁBIL")) -> HÁBIL
A13: JT | B13: 46112 | C13: R3 | D13: TARDE | E13: KOA | F13: ESTACIÓN TMS | G13: 0.76388889 | H13: =+G13+I13 -> 0.27083333 | I13: =+G14-G13 -> -0.49305556 | J13: 0.75902778 | K13: 0.76597222 | L13: =+K13-J13 -> 0.0069444444 | M13: =+K13+N13 -> 0.78298611 | N13: =AVERAGE(N11:N12) -> 0.017013889 | O13: =+L13+N13 -> 0.023958333 | P13: 1 | Q13: VIRREY Y POLO | R13: =IF(COUNTIF(fest!$A$1:$A$18,B13)>0,"FESTIVO", IF(OR(WEEKDAY(B13,2)=6,WEEKDAY(B13,2)=7),"NO HÁBIL","HÁBIL")) -> HÁBIL
A14: JM | B14: 46113 | C14: R1 | D14: MAÑANA | E14: ESTACIÓN TMS | F14: KOA | G14: 0.27083333 | H14: =+G14+I14 -> 0.29166667 | I14: =+G15-G14 -> 0.020833333 | J14: 0.26388889 | K14: 0.27638889 | L14: =+K14-J14 -> 0.0125 | M14: 0.28680556 | N14: =+M14-K14 -> 0.010416667 | O14: =+L14+N14 -> 0.022916667 | P14: 0 | Q14: OXXOHEROES | R14: =IF(COUNTIF(fest!$A$1:$A$18,B14)>0,"FESTIVO", IF(OR(WEEKDAY(B14,2)=6,WEEKDAY(B14,2)=7),"NO HÁBIL","HÁBIL")) -> HÁBIL
A15: JM | B15: 46113 | C15: R2 | D15: MAÑANA | E15: ESTACIÓN TMS | F15: KOA | G15: 0.29166667 | H15: =+G15+I15 -> 0.3125 | I15: =+G16-G15 -> 0.020833333 | J15: 0.28680556 | K15: 0.29375 | L15: =+K15-J15 -> 0.0069444444 | M15: 0.30972222 | N15: =+M15-K15 -> 0.015972222 | O15: =+L15+N15 -> 0.022916667 | P15: 2 | Q15: OXXOHEROES | R15: =IF(COUNTIF(fest!$A$1:$A$18,B15)>0,"FESTIVO", IF(OR(WEEKDAY(B15,2)=6,WEEKDAY(B15,2)=7),"NO HÁBIL","HÁBIL")) -> HÁBIL
A16: JM | B16: 46113 | C16: R3 | D16: MAÑANA | E16: ESTACIÓN TMS | F16: KOA | G16: 0.3125 | H16: =+G16+I16 -> 0.71527778 | I16: =+G17-G16 -> 0.40277778 | J16: 0.30972222 | K16: 0.32013889 | L16: =+K16-J16 -> 0.010416667 | M16: =+K16+N16 -> 0.33333333 | N16: =AVERAGE(N14:N15) -> 0.013194444 | O16: =+L16+N16 -> 0.023611111 | P16: 0 | Q16: OXXOHEROES | R16: =IF(COUNTIF(fest!$A$1:$A$18,B16)>0,"FESTIVO", IF(OR(WEEKDAY(B16,2)=6,WEEKDAY(B16,2)=7),"NO HÁBIL","HÁBIL")) -> HÁBIL
A17: JT | B17: 46113 | C17: R1 | D17: TARDE | E17: KOA | F17: ESTACIÓN TMS | G17: 0.71527778 | H17: =+G17+I17 -> 0.73958333 | I17: =+G18-G17 -> 0.024305556 | J17: 0.71111111 | K17: 0.71736111 | L17: =+K17-J17 -> 0.00625 | M17: 0.73541667 | N17: =+M17-K17 -> 0.018055556 | O17: =+L17+N17 -> 0.024305556 | P17: 4 | Q17: VIRREY Y POLO | R17: =IF(COUNTIF(fest!$A$1:$A$18,B17)>0,"FESTIVO", IF(OR(WEEKDAY(B17,2)=6,WEEKDAY(B17,2)=7),"NO HÁBIL","HÁBIL")) -> HÁBIL
A18: JT | B18: 46113 | C18: R2 | D18: TARDE | E18: KOA | F18: ESTACIÓN TMS | G18: 0.73958333 | H18: =+G18+I18 -> 0.76388889 | I18: =+G19-G18 -> 0.024305556 | J18: 0.73541667 | K18: 0.74444444 | L18: =+K18-J18 -> 0.0090277778 | M18: 0.75972222 | N18: =+M18-K18 -> 0.015277778 | O18: =+L18+N18 -> 0.024305556 | P18: 0 | Q18: NO SALIERON USUARIOS | R18: =IF(COUNTIF(fest!$A$1:$A$18,B18)>0,"FESTIVO", IF(OR(WEEKDAY(B18,2)=6,WEEKDAY(B18,2)=7),"NO HÁBIL","HÁBIL")) -> HÁBIL
A19: JT | B19: 46113 | C19: R3 | D19: TARDE | E19: KOA | F19: ESTACIÓN TMS | G19: 0.76388889 | H19: =+G19+I19 -> 0.27083333 | I19: =+G20-G19 -> -0.49305556 | J19: 0.75972222 | K19: 0.76597222 | L19: =+K19-J19 -> 0.00625 | M19: =+K19+N19 -> 0.78263889 | N19: =AVERAGE(N17:N18) -> 0.016666667 | O19: =+L19+N19 -> 0.022916667 | P19: 0 | Q19: NO SALIERON USUARIOS | R19: =IF(COUNTIF(fest!$A$1:$A$18,B19)>0,"FESTIVO", IF(OR(WEEKDAY(B19,2)=6,WEEKDAY(B19,2)=7),"NO HÁBIL","HÁBIL")) -> HÁBIL
A20: JM | B20: 46118 | C20: R1 | D20: MAÑANA | E20: ESTACIÓN TMS | F20: KOA | G20: 0.27083333 | H20: =+G20+I20 -> 0.29166667 | I20: =+G21-G20 -> 0.020833333 | J20: 0.26388889 | K20: 0.27361111 | L20: =+K20-J20 -> 0.0097222222 | M20: 0.28888889 | N20: =+M20-K20 -> 0.015277778 | O20: =+L20+N20 -> 0.025 | P20: 5 | Q20: OXXOHEROES | R20: =IF(COUNTIF(fest!$A$1:$A$18,B20)>0,"FESTIVO", IF(OR(WEEKDAY(B20,2)=6,WEEKDAY(B20,2)=7),"NO HÁBIL","HÁBIL")) -> HÁBIL
A21: JM | B21: 46118 | C21: R2 | D21: MAÑANA | E21: ESTACIÓN TMS | F21: KOA | G21: 0.29166667 | H21: =+G21+I21 -> 0.3125 | I21: =+G22-G21 -> 0.020833333 | J21: 0.28888889 | K21: 0.29444444 | L21: =+K21-J21 -> 0.0055555556 | M21: 0.31666667 | N21: =+M21-K21 -> 0.022222222 | O21: =+L21+N21 -> 0.027777778 | P21: 2 | Q21: OXXOHEROES | R21: =IF(COUNTIF(fest!$A$1:$A$18,B21)>0,"FESTIVO", IF(OR(WEEKDAY(B21,2)=6,WEEKDAY(B21,2)=7),"NO HÁBIL","HÁBIL")) -> HÁBIL
A22: JM | B22: 46118 | C22: R3 | D22: MAÑANA | E22: ESTACIÓN TMS | F22: KOA | G22: 0.3125 | H22: =+G22+I22 -> 0.71527778 | I22: =+G23-G22 -> 0.40277778 | J22: 0.31666667 | K22: 0.325 | L22: =+K22-J22 -> 0.0083333333 | M22: =+K22+N22 -> 0.34375 | N22: =AVERAGE(N20:N21) -> 0.01875 | O22: =+L22+N22 -> 0.027083333 | P22: 1 | Q22: OXXOHEROES | R22: =IF(COUNTIF(fest!$A$1:$A$18,B22)>0,"FESTIVO", IF(OR(WEEKDAY(B22,2)=6,WEEKDAY(B22,2)=7),"NO HÁBIL","HÁBIL")) -> HÁBIL
A23: JT | B23: 46118 | C23: R1 | D23: TARDE | E23: KOA | F23: ESTACIÓN TMS | G23: 0.71527778 | H23: =+G23+I23 -> 0.73958333 | I23: =+G24-G23 -> 0.024305556 | J23: 0.70833333 | K23: 0.71666667 | L23: =+K23-J23 -> 0.0083333333 | M23: 0.73541667 | N23: =+M23-K23 -> 0.01875 | O23: =+L23+N23 -> 0.027083333 | P23: 9 | Q23: VIRREY Y POLO | R23: =IF(COUNTIF(fest!$A$1:$A$18,B23)>0,"FESTIVO", IF(OR(WEEKDAY(B23,2)=6,WEEKDAY(B23,2)=7),"NO HÁBIL","HÁBIL")) -> HÁBIL
A24: JT | B24: 46118 | C24: R2 | D24: TARDE | E24: KOA | F24: ESTACIÓN TMS | G24: 0.73958333 | H24: =+G24+I24 -> 0.76388889 | I24: =+G25-G24 -> 0.024305556 | J24: 0.73541667 | K24: 0.74236111 | L24: =+K24-J24 -> 0.0069444444 | M24: 0.76180556 | N24: =+M24-K24 -> 0.019444444 | O24: =+L24+N24 -> 0.026388889 | P24: 2 | Q24: VIRREY Y POLO | R24: =IF(COUNTIF(fest!$A$1:$A$18,B24)>0,"FESTIVO", IF(OR(WEEKDAY(B24,2)=6,WEEKDAY(B24,2)=7),"NO HÁBIL","HÁBIL")) -> HÁBIL
A25: JT | B25: 46118 | C25: R3 | D25: TARDE | E25: KOA | F25: ESTACIÓN TMS | G25: 0.76388889 | H25: =+G25+I25 -> 0.27083333 | I25: =+G26-G25 -> -0.49305556 | J25: 0.76180556 | K25: 0.76666667 | L25: =+K25-J25 -> 0.0048611111 | M25: =+K25+N25 -> 0.78576389 | N25: =AVERAGE(N23:N24) -> 0.019097222 | O25: =+L25+N25 -> 0.023958333 | P25: 4 | Q25: VIRREY Y POLO | R25: =IF(COUNTIF(fest!$A$1:$A$18,B25)>0,"FESTIVO", IF(OR(WEEKDAY(B25,2)=6,WEEKDAY(B25,2)=7),"NO HÁBIL","HÁBIL")) -> HÁBIL
A26: JM | B26: 46119 | C26: R1 | D26: MAÑANA | E26: ESTACIÓN TMS | F26: KOA | G26: 0.27083333 | H26: =+G26+I26 -> 0.29166667 | I26: =+G27-G26 -> 0.020833333 | J26: 0.26388889 | K26: 0.27291667 | L26: =+K26-J26 -> 0.0090277778 | M26: 0.28819444 | N26: =+M26-K26 -> 0.015277778 | O26: =+L26+N26 -> 0.024305556 | P26: 1 | Q26: OXXOHEROES | R26: =IF(COUNTIF(fest!$A$1:$A$18,B26)>0,"FESTIVO", IF(OR(WEEKDAY(B26,2)=6,WEEKDAY(B26,2)=7),"NO HÁBIL","HÁBIL")) -> HÁBIL
A27: JM | B27: 46119 | C27: R2 | D27: MAÑANA | E27: ESTACIÓN TMS | F27: KOA | G27: 0.29166667 | H27: =+G27+I27 -> 0.3125 | I27: =+G28-G27 -> 0.020833333 | J27: 0.28819444 | K27: 0.29375 | L27: =+K27-J27 -> 0.0055555556 | M27: 0.30972222 | N27: =+M27-K27 -> 0.015972222 | O27: =+L27+N27 -> 0.021527778 | P27: 6 | Q27: OXXOHEROES | R27: =IF(COUNTIF(fest!$A$1:$A$18,B27)>0,"FESTIVO", IF(OR(WEEKDAY(B27,2)=6,WEEKDAY(B27,2)=7),"NO HÁBIL","HÁBIL")) -> HÁBIL
A28: JM | B28: 46119 | C28: R3 | D28: MAÑANA | E28: ESTACIÓN TMS | F28: KOA | G28: 0.3125 | H28: =+G28+I28 -> 0.70902778 | I28: =+G29-G28 -> 0.39652778 | J28: 0.30972222 | K28: 0.31458333 | L28: =+K28-J28 -> 0.0048611111 | M28: =+K28+N28 -> 0.33020833 | N28: =AVERAGE(N26:N27) -> 0.015625 | O28: =+L28+N28 -> 0.020486111 | P28: 1 | Q28: OXXOHEROES | R28: =IF(COUNTIF(fest!$A$1:$A$18,B28)>0,"FESTIVO", IF(OR(WEEKDAY(B28,2)=6,WEEKDAY(B28,2)=7),"NO HÁBIL","HÁBIL")) -> HÁBIL
A29: JT | B29: 46119 | C29: R1 | D29: TARDE | E29: KOA | F29: ESTACIÓN TMS | G29: 0.70902778 | H29: =+G29+I29 -> 0.73958333 | I29: =+G30-G29 -> 0.030555556 | J29: 0.70902778 | K29: 0.71666667 | L29: =+K29-J29 -> 0.0076388889 | M29: 0.75694444 | N29: =+M29-K29 -> 0.040277778 | O29: =+L29+N29 -> 0.047916667 | P29: 7 | Q29: POLO | R29: =IF(COUNTIF(fest!$A$1:$A$18,B29)>0,"FESTIVO", IF(OR(WEEKDAY(B29,2)=6,WEEKDAY(B29,2)=7),"NO HÁBIL","HÁBIL")) -> HÁBIL
A30: JT | B30: 46119 | C30: R2 | D30: TARDE | E30: KOA | F30: ESTACIÓN TMS | G30: 0.73958333 | H30: =+G30+I30 -> 0.76388889 | I30: =+G31-G30 -> 0.024305556 | J30: 0 | K30: 0 | L30: =+K30-J30 -> 0 | M30: 0 | N30: =+M30-K30 -> 0 | O30: =+L30+N30 -> 0 | P30: 0 | Q30: NO SE ALCANZO A REALIZAR RECORRIDO-CONGESTIÓN VH. | R30: =IF(COUNTIF(fest!$A$1:$A$18,B30)>0,"FESTIVO", IF(OR(WEEKDAY(B30,2)=6,WEEKDAY(B30,2)=7),"NO HÁBIL","HÁBIL")) -> HÁBIL
A31: JT | B31: 46119 | C31: R3 | D31: TARDE | E31: KOA | F31: ESTACIÓN TMS | G31: 0.76388889 | H31: =+G31+I31 -> 0.27083333 | I31: =+G32-G31 -> -0.49305556 | J31: 0.75694444 | K31: 0.76666667 | L31: =+K31-J31 -> 0.0097222222 | M31: =+K31+N31 -> 0.78680556 | N31: =AVERAGE(N29:N30) -> 0.020138889 | O31: =+L31+N31 -> 0.029861111 | P31: 6 | Q31: POLO | R31: =IF(COUNTIF(fest!$A$1:$A$18,B31)>0,"FESTIVO", IF(OR(WEEKDAY(B31,2)=6,WEEKDAY(B31,2)=7),"NO HÁBIL","HÁBIL")) -> HÁBIL
A32: JM | B32: 46120 | C32: R1 | D32: MAÑANA | E32: ESTACIÓN TMS | F32: KOA | G32: 0.27083333 | H32: =+G32+I32 -> 0.29166667 | I32: =+G33-G32 -> 0.020833333 | J32: 0.26388889 | K32: 0.27569444 | L32: =+K32-J32 -> 0.011805556 | M32: 0.28958333 | N32: =+M32-K32 -> 0.013888889 | O32: =+L32+N32 -> 0.025694444 | P32: 0 | Q32: OXXOHEROES | R32: =IF(COUNTIF(fest!$A$1:$A$18,B32)>0,"FESTIVO", IF(OR(WEEKDAY(B32,2)=6,WEEKDAY(B32,2)=7),"NO HÁBIL","HÁBIL")) -> HÁBIL
A33: JM | B33: 46120 | C33: R2 | D33: MAÑANA | E33: ESTACIÓN TMS | F33: KOA | G33: 0.29166667 | H33: =+G33+I33 -> 0.3125 | I33: =+G34-G33 -> 0.020833333 | J33: 0.28958333 | K33: 0.29375 | L33: =+K33-J33 -> 0.0041666667 | M33: 0.31041667 | N33: =+M33-K33 -> 0.016666667 | O33: =+L33+N33 -> 0.020833333 | P33: 3 | Q33: OXXOHEROES | R33: =IF(COUNTIF(fest!$A$1:$A$18,B33)>0,"FESTIVO", IF(OR(WEEKDAY(B33,2)=6,WEEKDAY(B33,2)=7),"NO HÁBIL","HÁBIL")) -> HÁBIL
A34: JM | B34: 46120 | C34: R3 | D34: MAÑANA | E34: ESTACIÓN TMS | F34: KOA | G34: 0.3125 | H34: =+G34+I34 -> 0.71527778 | I34: =+G35-G34 -> 0.40277778 | J34: 0.31041667 | K34: 0.32569444 | L34: =+K34-J34 -> 0.015277778 | M34: =+K34+N34 -> 0.34097222 | N34: =AVERAGE(N32:N33) -> 0.015277778 | O34: =+L34+N34 -> 0.030555556 | P34: 0 | Q34: OXXOHEROES | R34: =IF(COUNTIF(fest!$A$1:$A$18,B34)>0,"FESTIVO", IF(OR(WEEKDAY(B34,2)=6,WEEKDAY(B34,2)=7),"NO HÁBIL","HÁBIL")) -> HÁBIL
A35: JT | B35: 46120 | C35: R1 | D35: TARDE | E35: KOA | F35: ESTACIÓN TMS | G35: 0.71527778 | H35: =+G35+I35 -> 0.73958333 | I35: =+G36-G35 -> 0.024305556 | J35: 0.70833333 | K35: 0.71736111 | L35: =+K35-J35 -> 0.0090277778 | M35: 0.74166667 | N35: =+M35-K35 -> 0.024305556 | O35: =+L35+N35 -> 0.033333333 | P35: 5 | Q35: VIRREY Y POLO | R35: =IF(COUNTIF(fest!$A$1:$A$18,B35)>0,"FESTIVO", IF(OR(WEEKDAY(B35,2)=6,WEEKDAY(B35,2)=7),"NO HÁBIL","HÁBIL")) -> HÁBIL
A36: JT | B36: 46120 | C36: R2 | D36: TARDE | E36: KOA | F36: ESTACIÓN TMS | G36: 0.73958333 | H36: =+G36+I36 -> 0.76388889 | I36: =+G37-G36 -> 0.024305556 | J36: 0.74166667 | K36: 0.74652778 | L36: =+K36-J36 -> 0.0048611111 | M36: 0.7625 | N36: =+M36-K36 -> 0.015972222 | O36: =+L36+N36 -> 0.020833333 | P36: 0 | Q36: NO SALIERON USUARIOS | R36: =IF(COUNTIF(fest!$A$1:$A$18,B36)>0,"FESTIVO", IF(OR(WEEKDAY(B36,2)=6,WEEKDAY(B36,2)=7),"NO HÁBIL","HÁBIL")) -> HÁBIL
A37: JT | B37: 46120 | C37: R3 | D37: TARDE | E37: KOA | F37: ESTACIÓN TMS | G37: 0.76388889 | H37: =+G37+I37 -> 0.27083333 | I37: =+G38-G37 -> -0.49305556 | J37: 0.7625 | K37: 0.76666667 | L37: =+K37-J37 -> 0.0041666667 | M37: 0.77638889 | N37: =AVERAGE(N35:N36) -> 0.020138889 | O37: =+L37+N37 -> 0.024305556 | P37: 5 | Q37: VIRREY Y POLO | R37: =IF(COUNTIF(fest!$A$1:$A$18,B37)>0,"FESTIVO", IF(OR(WEEKDAY(B37,2)=6,WEEKDAY(B37,2)=7),"NO HÁBIL","HÁBIL")) -> HÁBIL
A38: JM | B38: 46121 | C38: R1 | D38: MAÑANA | E38: ESTACIÓN TMS | F38: KOA | G38: 0.27083333 | H38: =+G38+I38 -> 0.29166667 | I38: =+G39-G38 -> 0.020833333 | J38: 0.26388889 | K38: 0.27291667 | L38: =+K38-J38 -> 0.0090277778 | M38: 0.28819444 | N38: =+M38-K38 -> 0.015277778 | O38: =+L38+N38 -> 0.024305556 | P38: 1 | Q38: OXXOHEROES | R38: =IF(COUNTIF(fest!$A$1:$A$18,B38)>0,"FESTIVO", IF(OR(WEEKDAY(B38,2)=6,WEEKDAY(B38,2)=7),"NO HÁBIL","HÁBIL")) -> HÁBIL
A39: JM | B39: 46121 | C39: R2 | D39: MAÑANA | E39: ESTACIÓN TMS | F39: KOA | G39: 0.29166667 | H39: =+G39+I39 -> 0.3125 | I39: =+G40-G39 -> 0.020833333 | J39: 0.28819444 | K39: 0.29375 | L39: =+K39-J39 -> 0.0055555556 | M39: 0.31388889 | N39: =+M39-K39 -> 0.020138889 | O39: =+L39+N39 -> 0.025694444 | P39: 4 | Q39: OXXOHEROES | R39: =IF(COUNTIF(fest!$A$1:$A$18,B39)>0,"FESTIVO", IF(OR(WEEKDAY(B39,2)=6,WEEKDAY(B39,2)=7),"NO HÁBIL","HÁBIL")) -> HÁBIL
A40: JM | B40: 46121 | C40: R3 | D40: MAÑANA | E40: ESTACIÓN TMS | F40: KOA | G40: 0.3125 | H40: =+G40+I40 -> 0.71527778 | I40: =+G41-G40 -> 0.40277778 | J40: 0.31388889 | K40: 0.31458333 | L40: =+K40-J40 -> 0.00069444444 | M40: =+K40+N40 -> 0.33229167 | N40: =AVERAGE(N38:N39) -> 0.017708333 | O40: =+L40+N40 -> 0.018402778 | P40: 1 | Q40: OXXOHEROES | R40: =IF(COUNTIF(fest!$A$1:$A$18,B40)>0,"FESTIVO", IF(OR(WEEKDAY(B40,2)=6,WEEKDAY(B40,2)=7),"NO HÁBIL","HÁBIL")) -> HÁBIL
...
